Workbook
Name Calculator_type: #REF!
Name CommitmentIndexList: TRANSPOSE(IF(VLOOKUP('Solution-based'!$B$3,#REF!,3,FALSE)="YES",_xlfn.SEQUENCE(8),_xlfn.SEQUENCE(7)))
Name CommitmentList: INDIRECT("'Pricelist "&'Solution-based'!$B$3&"'!$G$2:$N$2")
Name Currency: #REF!
Name min_commit: 'Pricelist USD'!$G$2:$M$2
Name min_commit: 'Pricelist USD'!$G$2:$M$2
Name T_1: #REF!
Name T_2: #REF!
Name T_3: #REF!
Name T_4: #REF!
Name T_5: #REF!

Sheet Solution-based
A2: Currency | B2: USD
A3: Calculator type | B3: USD
A4: Solution-based Licensing | E4: =IF(E5<>'Service-based'!E3,"Monthly minimum commitment inconsistency. Select the same commitment for both licensing options","")
A5: 1. Choose Minimum commitment: | D5: =MATCH(E5,INDIRECT("'Pricelist "&$B$3&"'!$G$2:$N$2"),0) -> 1 | E5: 250 | F5: {=IFERROR(IF(AND(B3="JPY",E5=30000),"Only for SPs that already have this commitment",IF(D5=1,IF(G53>'Calculator +1 tier'!F118,"Recommended to switch to higher commitment",""),IF(AND(D5=8,'Calculator -1 tier'!F117>INDIRECT("'Pricelist "&B3&"'!N2")),"",IF(G53>'Calculator -1 tier'!F118,"Recommended to switch to lower commitment",IF(G53>'Calculator +1 tier'!F118,"Recommended to switch to higher commitment",""))))),"")}
A6: 2. Choose Datacenter Group: | E6: G1 | F6: =IF(E6<>'Service-based'!E4,"Select the same DC group for both licensing options","")
A7: 3. Input data for endpoints to be protected (Solution-based Licensing): | D7: Stand-alone capabilities | E7: Quantity | F7: Price per unit (monthly) | G7: Total cost
A8: Security + RMM | C8: # Endpoint Security (Servers, VMs, Workstations) | D8: Yes | F8: =IF(E8>0,IFERROR(SUMIFS(INDIRECT("'Pricelist "&$B$3&"'!$"&CHAR(70+$D$5)&"$3:$"&CHAR(70+$D$5)&"$130"),INDIRECT("'Pricelist "&$B$3&"'!$O$3:$O$130"),C8),"Pricelist not found"),"") | G8: =IFERROR(E8*F8,"")
C9: # Microsoft 365 Security | F9: =IF(E9>0,IFERROR(SUMIFS(INDIRECT("'Pricelist "&$B$3&"'!$"&CHAR(70+$D$5)&"$3:$"&CHAR(70+$D$5)&"$130"),INDIRECT("'Pricelist "&$B$3&"'!$O$3:$O$130"),C9),"Pricelist not found"),"") | G9: =IFERROR(E9*F9,"")
C10: # Google Workspace Security | F10: =IF(E10>0,IFERROR(SUMIFS(INDIRECT("'Pricelist "&$B$3&"'!$"&CHAR(70+$D$5)&"$3:$"&CHAR(70+$D$5)&"$130"),INDIRECT("'Pricelist "&$B$3&"'!$O$3:$O$130"),C10),"Pricelist not found"),"") | G10: =IFERROR(E10*F10,"")
A11: Backup + DR | C11: # BDR Server (3 TB of Acronis Hosted Storage included) | D11: Yes | F11: =IF(E11>0,IFERROR(SUMIFS(INDIRECT("'Pricelist "&$B$3&"'!$"&CHAR(70+$D$5)&"$3:$"&CHAR(70+$D$5)&"$130"),INDIRECT("'Pricelist "&$B$3&"'!$O$3:$O$130"),C11,INDIRECT("'Pricelist "&$B$3&"'!$E$3:$E$130"),$E$6),"Pricelist not found"),"") | G11: =IFERROR(E11*F11,"")
C12: # BDR Virtual Machine (2 TB of Acronis Hosted Storage included) | F12: =IF(E12>0,IFERROR(SUMIFS(INDIRECT("'Pricelist "&$B$3&"'!$"&CHAR(70+$D$5)&"$3:$"&CHAR(70+$D$5)&"$130"),INDIRECT("'Pricelist "&$B$3&"'!$O$3:$O$130"),C12,INDIRECT("'Pricelist "&$B$3&"'!$E$3:$E$130"),$E$6),"Pricelist not found"),"") | G12: =IFERROR(E12*F12,"")
C13: # BDR Workstation (300 GB of Acronis Hosted Storage included) | F13: =IF(E13>0,IFERROR(SUMIFS(INDIRECT("'Pricelist "&$B$3&"'!$"&CHAR(70+$D$5)&"$3:$"&CHAR(70+$D$5)&"$130"),INDIRECT("'Pricelist "&$B$3&"'!$O$3:$O$130"),C13,INDIRECT("'Pricelist "&$B$3&"'!$E$3:$E$130"),$E$6),"Pricelist not found"),"") | G13: =IFERROR(E13*F13,"")
C14: # Microsoft 365 Backup + Archiving (unlimited Acronis Hosted Cloud Storage included*) | F14: =IF(E14>0,IFERROR(SUMIFS(INDIRECT("'Pricelist "&$B$3&"'!$"&CHAR(70+$D$5)&"$3:$"&CHAR(70+$D$5)&"$130"),INDIRECT("'Pricelist "&$B$3&"'!$O$3:$O$130"),C14,INDIRECT("'Pricelist "&$B$3&"'!$E$3:$E$130"),$E$6),"Pricelist not found"),"") | G14: =IFERROR(E14*F14,"")
C15: # Google Workspace Backup (unlimited Acronis Hosted Cloud Storage included*) | F15: =IF(E15>0,IFERROR(SUMIFS(INDIRECT("'Pricelist "&$B$3&"'!$"&CHAR(70+$D$5)&"$3:$"&CHAR(70+$D$5)&"$130"),INDIRECT("'Pricelist "&$B$3&"'!$O$3:$O$130"),C15,INDIRECT("'Pricelist "&$B$3&"'!$E$3:$E$130"),$E$6),"Pricelist not found"),"") | G15: =IFERROR(E15*F15,"")
C16: # Mobile Backup (50 GB od Acronis Hosted Storage included) | F16: =IF(E16>0,IFERROR(SUMIFS(INDIRECT("'Pricelist "&$B$3&"'!$"&CHAR(70+$D$5)&"$3:$"&CHAR(70+$D$5)&"$130"),INDIRECT("'Pricelist "&$B$3&"'!$O$3:$O$130"),C16,INDIRECT("'Pricelist "&$B$3&"'!$E$3:$E$130"),$E$6),"Pricelist not found"),"") | G16: =IFERROR(E16*F16,"")
A17: Ultimate Protection | C17: # Ultimate Server (3 TB of Acronis Hosted Storage included) | D17: Yes | F17: =IF(E17>0,IFERROR(SUMIFS(INDIRECT("'Pricelist "&$B$3&"'!$"&CHAR(70+$D$5)&"$3:$"&CHAR(70+$D$5)&"$130"),INDIRECT("'Pricelist "&$B$3&"'!$O$3:$O$130"),C17,INDIRECT("'Pricelist "&$B$3&"'!$E$3:$E$130"),$E$6),"Pricelist not found"),"") | G17: =IFERROR(E17*F17,"")
C18: # Ultimate Virtual Machine (2 TB of Acronis Hosted Storage included) | F18: =IF(E18>0,IFERROR(SUMIFS(INDIRECT("'Pricelist "&$B$3&"'!$"&CHAR(70+$D$5)&"$3:$"&CHAR(70+$D$5)&"$130"),INDIRECT("'Pricelist "&$B$3&"'!$O$3:$O$130"),C18,INDIRECT("'Pricelist "&$B$3&"'!$E$3:$E$130"),$E$6),"Pricelist not found"),"") | G18: =IFERROR(E18*F18,"")
C19: # Ultimate Workstation (300 GB of Acronis Hosted Storage included) | F19: =IF(E19>0,IFERROR(SUMIFS(INDIRECT("'Pricelist "&$B$3&"'!$"&CHAR(70+$D$5)&"$3:$"&CHAR(70+$D$5)&"$130"),INDIRECT("'Pricelist "&$B$3&"'!$O$3:$O$130"),C19,INDIRECT("'Pricelist "&$B$3&"'!$E$3:$E$130"),$E$6),"Pricelist not found"),"") | G19: =IFERROR(E19*F19,"")
C20: # Ultimate Microsoft 365 (unlimited Acronis Hosted Cloud Storage included*) | F20: =IF(E20>0,IFERROR(SUMIFS(INDIRECT("'Pricelist "&$B$3&"'!$"&CHAR(70+$D$5)&"$3:$"&CHAR(70+$D$5)&"$130"),INDIRECT("'Pricelist "&$B$3&"'!$O$3:$O$130"),C20,INDIRECT("'Pricelist "&$B$3&"'!$E$3:$E$130"),$E$6),"Pricelist not found"),"") | G20: =IFERROR(E20*F20,"")
C21: # Ultimate Google Workspace (unlimited Acronis Hosted Cloud Storage included*) | F21: =IF(E21>0,IFERROR(SUMIFS(INDIRECT("'Pricelist "&$B$3&"'!$"&CHAR(70+$D$5)&"$3:$"&CHAR(70+$D$5)&"$130"),INDIRECT("'Pricelist "&$B$3&"'!$O$3:$O$130"),C21,INDIRECT("'Pricelist "&$B$3&"'!$E$3:$E$130"),$E$6),"Pricelist not found"),"") | G21: =IFERROR(E21*F21,"")
A22: 4. Input data for endpoints to be protected (Additional Services):
A23: Managed Detection and Response | C23: # Standard In-house MDR Workloads for Solution-Base Licensing, Partner-level (Servers, VMs, Workstations, Hosting Servers) | D23: Requires Security+RMM or Ultimate Protection | F23: =IF(E23>0,IFERROR(SUMIFS(INDIRECT("'Pricelist "&$B$3&"'!$"&CHAR(70+$D$5)&"$3:$"&CHAR(70+$D$5)&"$130"),INDIRECT("'Pricelist "&$B$3&"'!$O$3:$O$130"),C23),"Pricelist not found"),"") | G23: =IFERROR(E23*F23,"")
C24: # Advanced In-house MDR Workloads for Solution-Base Licensing, Partner-level (Servers, VMs, Workstations, Hosting Servers) | F24: =IF(E24>0,IFERROR(SUMIFS(INDIRECT("'Pricelist "&$B$3&"'!$"&CHAR(70+$D$5)&"$3:$"&CHAR(70+$D$5)&"$130"),INDIRECT("'Pricelist "&$B$3&"'!$O$3:$O$130"),C24),"Pricelist not found"),"") | G24: =IFERROR(E24*F24,"")
C25: # Standard In-house MDR Workloads for Solution-Base Licensing, Customer-level (Servers, VMs, Workstations, Hosting Servers) | F25: =IF(E25>0,IFERROR(SUMIFS(INDIRECT("'Pricelist "&$B$3&"'!$"&CHAR(70+$D$5)&"$3:$"&CHAR(70+$D$5)&"$130"),INDIRECT("'Pricelist "&$B$3&"'!$O$3:$O$130"),C25),"Pricelist not found"),"") | G25: =IFERROR(E25*F25,"")
C26: # Advanced In-house MDR Workloads for Solution-Base Licensing, Customer-level (Servers, VMs, Workstations, Hosting Servers) | F26: =IF(E26>0,IFERROR(SUMIFS(INDIRECT("'Pricelist "&$B$3&"'!$"&CHAR(70+$D$5)&"$3:$"&CHAR(70+$D$5)&"$130"),INDIRECT("'Pricelist "&$B$3&"'!$O$3:$O$130"),C26),"Pricelist not found"),"") | G26: =IFERROR(E26*F26,"")
C27: # Standard 3rd Party MDR Workloads for Solution-Base Licensing (Servers, VMs, Workstations, Hosting Servers) | F27: =IF(E27>0,IFERROR(SUMIFS(INDIRECT("'Pricelist "&$B$3&"'!$"&CHAR(70+$D$5)&"$3:$"&CHAR(70+$D$5)&"$130"),INDIRECT("'Pricelist "&$B$3&"'!$O$3:$O$130"),C27),"Pricelist not found"),"") | G27: =IFERROR(E27*F27,"")
C28: # Advanced 3rd Party MDR Workloads for Solution-Base Licensing (Servers, VMs, Workstations, Hosting Servers) | F28: =IF(E28>0,IFERROR(SUMIFS(INDIRECT("'Pricelist "&$B$3&"'!$"&CHAR(70+$D$5)&"$3:$"&CHAR(70+$D$5)&"$130"),INDIRECT("'Pricelist "&$B$3&"'!$O$3:$O$130"),C28),"Pricelist not found"),"") | G28: =IFERROR(E28*F28,"")
A29: Security Awareness Training | C29: # Security Awareness Training for Solution-based Licensing (Users) | D29: Yes | F29: =IF(E29>0,IFERROR(SUMIFS(INDIRECT("'Pricelist "&$B$3&"'!$"&CHAR(70+$D$5)&"$3:$"&CHAR(70+$D$5)&"$130"),INDIRECT("'Pricelist "&$B$3&"'!$O$3:$O$130"),C29),"Pricelist not found"),"") | G29: =IFERROR(E29*F29,"")
A30: Additional Storage | C30: Acronis Cloud Storage at Acronis Datacenter (for Solution-based Licensing overages) | D30: Requires BDR or Ultimate Protection | F30: =IF(E30>0,IFERROR(SUMIFS(INDIRECT("'Pricelist "&$B$3&"'!$"&CHAR(70+$D$5)&"$3:$"&CHAR(70+$D$5)&"$130"),INDIRECT("'Pricelist "&$B$3&"'!$O$3:$O$130"),C30,INDIRECT("'Pricelist "&$B$3&"'!$E$3:$E$130"),$E$6),"Pricelist not found"),"") | G30: =IFERROR(E30*F30,"")
A31: Geo-replication | C31: Solution-based licensing - Backup Geo-redundant - Acronis Hosted Storage | D31: Requires BDR or Ultimate Protection | F31: =IF(AND(E31>0,$E$6="G2"),"Not available for G2",IF(E31>0,IFERROR(SUMIFS(INDIRECT("'Pricelist "&$B$3&"'!$"&CHAR(70+$D$5)&"$3:$"&CHAR(70+$D$5)&"$130"),INDIRECT("'Pricelist "&$B$3&"'!$O$3:$O$130"),C31),"Pricelist not found"),"")) | G31: =IFERROR(E31*F31,"")
C32: Solution-based licensing - # Geo-redundant Microsoft 365 seat (unlimited Acronis Hosted Cloud Storage included*) | F32: =IF(AND(E32>0,$E$6="G2"),"Not available for G2",IF(E32>0,IFERROR(SUMIFS(INDIRECT("'Pricelist "&$B$3&"'!$"&CHAR(70+$D$5)&"$3:$"&CHAR(70+$D$5)&"$130"),INDIRECT("'Pricelist "&$B$3&"'!$O$3:$O$130"),C32),"Pricelist not found"),"")) | G32: =IFERROR(E32*F32,"")
C33: Solution-based licensing - # Geo-redundant Google Workspace seat (unlimited Acronis Hosted Cloud Storage included*) | F33: =IF(AND(E33>0,$E$6="G2"),"Not available for G2",IF(E33>0,IFERROR(SUMIFS(INDIRECT("'Pricelist "&$B$3&"'!$"&CHAR(70+$D$5)&"$3:$"&CHAR(70+$D$5)&"$130"),INDIRECT("'Pricelist "&$B$3&"'!$O$3:$O$130"),C33),"Pricelist not found"),"")) | G33: =IFERROR(E33*F33,"")
A34: Disaster Recovery Infrastructure | C34: Monthly Compute Point Consumption for BDR/Ultimate | D34: Requires BDR or Ultimate Protection | E34: =IF('Compute points'!E13=0,"",'Compute points'!E13) | F34: =IF(E34<>"",IFERROR(SUMIFS(INDIRECT("'Pricelist "&$B$3&"'!$"&CHAR(70+$D$5)&"$3:$"&CHAR(70+$D$5)&"$130"),INDIRECT("'Pricelist "&$B$3&"'!$O$3:$O$130"),C34),"Pricelist not found"),"") | G34: =IFERROR(E34*F34,"")
C35: Public IPs for BDR/Ultimate | F35: =IF(E35>0,IFERROR(SUMIFS(INDIRECT("'Pricelist "&$B$3&"'!$"&CHAR(70+$D$5)&"$3:$"&CHAR(70+$D$5)&"$130"),INDIRECT("'Pricelist "&$B$3&"'!$O$3:$O$130"),C35),"Pricelist not found"),"") | G35: =IFERROR(E35*F35,"")
A36: 5. Input data for Cyber Frame, Cyber Workspace, FSS, ACI and Archival Storage
A37: Cyber Frame | B37: Cyber Frame Local | C37: # Physical Cores, Standard Support Included | D37: Yes | F37: =IF(E37>0,IFERROR(SUMIFS(INDIRECT("'Pricelist "&$B$3&"'!$"&CHAR(70+$D$5)&"$3:$"&CHAR(70+$D$5)&"$130"),INDIRECT("'Pricelist "&$B$3&"'!$O$3:$O$130"),C37),"Pricelist not found"),"") | G37: =IFERROR(E37*F37,"")
B38: Cyber Frame Cloud | C38: # Used Standard vCPUs | D38: Yes | F38: =IF(E38>0,IFERROR(SUMIFS(INDIRECT("'Pricelist "&$B$3&"'!$"&CHAR(70+$D$5)&"$3:$"&CHAR(70+$D$5)&"$130"),INDIRECT("'Pricelist "&$B$3&"'!$O$3:$O$130"),C38),"Pricelist not found"),"") | G38: =IFERROR(E38*F38,"")
C39: # GB of used Standard RAM | F39: =IF(E39<>"",IFERROR(SUMIFS(INDIRECT("'Pricelist "&$B$3&"'!$"&CHAR(70+$D$5)&"$3:$"&CHAR(70+$D$5)&"$130"),INDIRECT("'Pricelist "&$B$3&"'!$O$3:$O$130"),C39),"Pricelist not found"),"") | G39: =IFERROR(E39*F39,"")
C40: Cyber Frame Cloud Block Storage | F40: =IF(E40>0,IFERROR(SUMIFS(INDIRECT("'Pricelist "&$B$3&"'!$"&CHAR(70+$D$5)&"$3:$"&CHAR(70+$D$5)&"$130"),INDIRECT("'Pricelist "&$B$3&"'!$O$3:$O$130"),C40),"Pricelist not found"),"") | G40: =IFERROR(E40*F40,"")
C41: # Public IPs for Cyber Frame Cloud | F41: =IF(E41>0,IFERROR(SUMIFS(INDIRECT("'Pricelist "&$B$3&"'!$"&CHAR(70+$D$5)&"$3:$"&CHAR(70+$D$5)&"$130"),INDIRECT("'Pricelist "&$B$3&"'!$O$3:$O$130"),C41),"Pricelist not found"),"") | G41: =IFERROR(E41*F41,"")
...

Sheet Service-based
A1: #VALUE!
A2: Service-based Licensing | E2: =IF(E3<>'Solution-based'!E5,"Monthly minimum commitment inconsistency. Select the same commitment for both licensing options","")
A3: 1. Choose Minimum commitment: | D3: =MATCH(E3,INDIRECT("'Pricelist "&'Solution-based'!$B$3&"'!$G$2:$N$2"),0) -> 1 | E3: 250 | F3: {=IFERROR(IF(AND('Solution-based'!B3="JPY",E3=30000),"Only for SPs that already have this commitment",IF(D3=1,IF(G76>'Calculator +1 tier'!F118,"Recommended to switch to higher commitment",""),IF(AND(D3=8,'Calculator -1 tier'!F117>INDIRECT("'Pricelist "&'Solution-based'!B3&"'!N2")),"",IF(G76>'Calculator -1 tier'!F118,"Recommended to switch to lower commitment",IF(G76>'Calculator +1 tier'!F118,"Recommended to switch to higher commitment",""))))),"")}
A4: 2. Choose Datacenter Group: | E4: G1 | F4: =IF(E4<>'Solution-based'!E6,"Select the same DC group for both licensing options","")
A5: 3. Input data for endpoints and storage to be protected (Service-based Licensing): | D5: Stand-alone capabilities | E5: Quantity | F5: Price per unit (monthly) | G5: Total cost
A6: Endpoint Security | C6: # Endpoint Detection and Response (EDR) Workloads (Servers, VMs, Workstations, Hosting Servers) | D6: Yes | F6: =IF(E6>0,IFERROR(SUMIFS(INDIRECT("'Pricelist "&'Solution-based'!$B$3&"'!$"&CHAR(70+$D$3)&"$30:$"&CHAR(70+$D$3)&"$130"),INDIRECT("'Pricelist "&'Solution-based'!$B$3&"'!$O$30:$O$130"),C6),"Pricelist not found"),"") | G6: =IFERROR(E6*F6,"")
C7: # Extended Detection and Response (XDR) Workloads (Servers, VMs, Workstations, Hosting Servers) | F7: =IF(E7>0,IFERROR(SUMIFS(INDIRECT("'Pricelist "&'Solution-based'!$B$3&"'!$"&CHAR(70+$D$3)&"$30:$"&CHAR(70+$D$3)&"$130"),INDIRECT("'Pricelist "&'Solution-based'!$B$3&"'!$O$30:$O$130"),C7),"Pricelist not found"),"") | G7: =IFERROR(E7*F7,"")
C8: # In-house MDR Workloads - Standard - Partner-level (Servers, VMs, Workstations, Hosting Servers) | D8: Requires EDR/XDR | F8: =IF(E8>0,IFERROR(SUMIFS(INDIRECT("'Pricelist "&'Solution-based'!$B$3&"'!$"&CHAR(70+$D$3)&"$30:$"&CHAR(70+$D$3)&"$130"),INDIRECT("'Pricelist "&'Solution-based'!$B$3&"'!$O$30:$O$130"),C8),"Pricelist not found"),"") | G8: =IFERROR(E8*F8,"")
C9: # In-house MDR Workloads - Advanced - Partner-level (Servers, VMs, Workstations, Hosting Servers) | F9: =IF(E9>0,IFERROR(SUMIFS(INDIRECT("'Pricelist "&'Solution-based'!$B$3&"'!$"&CHAR(70+$D$3)&"$30:$"&CHAR(70+$D$3)&"$130"),INDIRECT("'Pricelist "&'Solution-based'!$B$3&"'!$O$30:$O$130"),C9),"Pricelist not found"),"") | G9: =IFERROR(E9*F9,"")
C10: # In-house MDR Workloads - Standard - Customer-level (Servers, VMs, Workstations, Hosting Servers) | F10: =IF(E10>0,IFERROR(SUMIFS(INDIRECT("'Pricelist "&'Solution-based'!$B$3&"'!$"&CHAR(70+$D$3)&"$30:$"&CHAR(70+$D$3)&"$130"),INDIRECT("'Pricelist "&'Solution-based'!$B$3&"'!$O$30:$O$130"),C10),"Pricelist not found"),"") | G10: =IFERROR(E10*F10,"")
C11: # In-house MDR Workloads - Advanced - Customer-level (Servers, VMs, Workstations, Hosting Servers) | F11: =IF(E11>0,IFERROR(SUMIFS(INDIRECT("'Pricelist "&'Solution-based'!$B$3&"'!$"&CHAR(70+$D$3)&"$30:$"&CHAR(70+$D$3)&"$130"),INDIRECT("'Pricelist "&'Solution-based'!$B$3&"'!$O$30:$O$130"),C11),"Pricelist not found"),"") | G11: =IFERROR(E11*F11,"")
C12: # 3rd Party MDR Workloads - Standard (Servers, VMs, Workstations, Hosting Servers) | F12: =IF(E12>0,IFERROR(SUMIFS(INDIRECT("'Pricelist "&'Solution-based'!$B$3&"'!$"&CHAR(70+$D$3)&"$30:$"&CHAR(70+$D$3)&"$130"),INDIRECT("'Pricelist "&'Solution-based'!$B$3&"'!$O$30:$O$130"),C12),"Pricelist not found"),"") | G12: =IFERROR(E12*F12,"")
C13: # 3rd Party MDR Workloads - Advanced (Servers, VMs, Workstations, Hosting Servers) | F13: =IF(E13>0,IFERROR(SUMIFS(INDIRECT("'Pricelist "&'Solution-based'!$B$3&"'!$"&CHAR(70+$D$3)&"$30:$"&CHAR(70+$D$3)&"$130"),INDIRECT("'Pricelist "&'Solution-based'!$B$3&"'!$O$30:$O$130"),C13),"Pricelist not found"),"") | G13: =IFERROR(E13*F13,"")
C14: # Gen AI Protection Workloads | D14: Yes | F14: =IF(E14>0,IFERROR(SUMIFS(INDIRECT("'Pricelist "&'Solution-based'!$B$3&"'!$"&CHAR(70+$D$3)&"$30:$"&CHAR(70+$D$3)&"$130"),INDIRECT("'Pricelist "&'Solution-based'!$B$3&"'!$O$30:$O$130"),C14),"Pricelist not found"),"") | G14: =IFERROR(E14*F14,"")
C15: # Data Loss Prevention Workloads (Servers, VMs, Workstations, Hosting Servers) | D15: Yes | F15: =IF(E15>0,IFERROR(SUMIFS(INDIRECT("'Pricelist "&'Solution-based'!$B$3&"'!$"&CHAR(70+$D$3)&"$30:$"&CHAR(70+$D$3)&"$130"),INDIRECT("'Pricelist "&'Solution-based'!$B$3&"'!$O$30:$O$130"),C15),"Pricelist not found"),"") | G15: =IFERROR(E15*F15,"")
A16: SaaS Security | C16: # Email Security Users | D16: Yes | F16: =IF(E16>0,IFERROR(SUMIFS(INDIRECT("'Pricelist "&'Solution-based'!$B$3&"'!$"&CHAR(70+$D$3)&"$30:$"&CHAR(70+$D$3)&"$130"),INDIRECT("'Pricelist "&'Solution-based'!$B$3&"'!$O$30:$O$130"),C16),"Pricelist not found"),"") | G16: =IFERROR(E16*F16,"")
C17: # Collaboration Security Users | F17: =IF(E17>0,IFERROR(SUMIFS(INDIRECT("'Pricelist "&'Solution-based'!$B$3&"'!$"&CHAR(70+$D$3)&"$30:$"&CHAR(70+$D$3)&"$130"),INDIRECT("'Pricelist "&'Solution-based'!$B$3&"'!$O$30:$O$130"),C17),"Pricelist not found"),"") | G17: =IFERROR(E17*F17,"")
C18: # SaaS Security Posture Management Workloads (Microsoft 365 Seats) | F18: =IF(E18>0,IFERROR(SUMIFS(INDIRECT("'Pricelist "&'Solution-based'!$B$3&"'!$"&CHAR(70+$D$3)&"$42:$"&CHAR(70+$D$3)&"$130"),INDIRECT("'Pricelist "&'Solution-based'!$B$3&"'!$O$42:$O$130"),C18),"Pricelist not found"),"") | G18: =IFERROR(E18*F18,"")
A19: Security Awareness Training | C19: # Security Awareness Training (Users) | D19: Yes | F19: =IF(E19>0,IFERROR(SUMIFS(INDIRECT("'Pricelist "&'Solution-based'!$B$3&"'!$"&CHAR(70+$D$3)&"$42:$"&CHAR(70+$D$3)&"$130"),INDIRECT("'Pricelist "&'Solution-based'!$B$3&"'!$O$42:$O$130"),C19),"Pricelist not found"),"") | G19: =IFERROR(E19*F19,"")
A20: RMM | C20: # Remote Monitoring and Management (RMM) Workloads (Servers, VMs, Workstations, Hosting Servers) | D20: Yes | F20: =IF(E20>0,IFERROR(SUMIFS(INDIRECT("'Pricelist "&'Solution-based'!$B$3&"'!$"&CHAR(70+$D$3)&"$42:$"&CHAR(70+$D$3)&"$130"),INDIRECT("'Pricelist "&'Solution-based'!$B$3&"'!$O$42:$O$130"),C20),"Pricelist not found"),"") | G20: =IFERROR(E20*F20,"")
A21: PSA | C21: # Professional Services Automation (PSA) users (3 minimum) | D21: Yes | F21: =IF(E21>0,IFERROR(SUMIFS(INDIRECT("'Pricelist "&'Solution-based'!$B$3&"'!$"&CHAR(70+$D$3)&"$42:$"&CHAR(70+$D$3)&"$130"),INDIRECT("'Pricelist "&'Solution-based'!$B$3&"'!$O$42:$O$130"),C21),"Pricelist not found"),"") | G21: =IFERROR(E21*F21,"")
A22: Backup | B22: Per Workload | C22: # Physical Servers | D22: Yes | F22: =IF(E22>0,IFERROR(SUMIFS(INDIRECT("'Pricelist "&'Solution-based'!$B$3&"'!$"&CHAR(70+$D$3)&"$42:$"&CHAR(70+$D$3)&"$130"),INDIRECT("'Pricelist "&'Solution-based'!$B$3&"'!$O$42:$O$130"),C22),"Pricelist not found"),"") | G22: =IFERROR(E22*F22,"")
C23: # Network Attached Storage | F23: =IF(E23>0,IFERROR(SUMIFS(INDIRECT("'Pricelist "&'Solution-based'!$B$3&"'!$"&CHAR(70+$D$3)&"$42:$"&CHAR(70+$D$3)&"$130"),INDIRECT("'Pricelist "&'Solution-based'!$B$3&"'!$O$42:$O$130"),C23),"Pricelist not found"),"") | G23: =IFERROR(E23*F23,"")
C24: # Virtual Machines | F24: =IF(E24>0,IFERROR(SUMIFS(INDIRECT("'Pricelist "&'Solution-based'!$B$3&"'!$"&CHAR(70+$D$3)&"$42:$"&CHAR(70+$D$3)&"$130"),INDIRECT("'Pricelist "&'Solution-based'!$B$3&"'!$O$42:$O$130"),C24),"Pricelist not found"),"") | G24: =IFERROR(E24*F24,"")
C25: # Workstations | F25: =IF(E25>0,IFERROR(SUMIFS(INDIRECT("'Pricelist "&'Solution-based'!$B$3&"'!$"&CHAR(70+$D$3)&"$42:$"&CHAR(70+$D$3)&"$130"),INDIRECT("'Pricelist "&'Solution-based'!$B$3&"'!$O$42:$O$130"),C25),"Pricelist not found"),"") | G25: =IFERROR(E25*F25,"")
C26: # Hosting Servers | F26: =IF(E26>0,IFERROR(SUMIFS(INDIRECT("'Pricelist "&'Solution-based'!$B$3&"'!$"&CHAR(70+$D$3)&"$42:$"&CHAR(70+$D$3)&"$130"),INDIRECT("'Pricelist "&'Solution-based'!$B$3&"'!$O$42:$O$130"),C26),"Pricelist not found"),"") | G26: =IFERROR(E26*F26,"")
C27: # Microsoft 365 Seats (unlimited Acronis Hosted Cloud Storage included*) | F27: =IF(E27>0,IFERROR(SUMIFS(INDIRECT("'Pricelist "&'Solution-based'!$B$3&"'!$"&CHAR(70+$D$3)&"$42:$"&CHAR(70+$D$3)&"$130"),INDIRECT("'Pricelist "&'Solution-based'!$B$3&"'!$O$42:$O$130"),C27,INDIRECT("'Pricelist "&'Solution-based'!$B$3&"'!$E$42:$E$130"),$E$4),"Pricelist not found"),"") | G27: =IFERROR(E27*F27,"")
C28: # Microsoft 365 Seats (for SP/Customer/Azure/Google Hosted Storage) | F28: =IF(E28>0,IFERROR(SUMIFS(INDIRECT("'Pricelist "&'Solution-based'!$B$3&"'!$"&CHAR(70+$D$3)&"$42:$"&CHAR(70+$D$3)&"$130"),INDIRECT("'Pricelist "&'Solution-based'!$B$3&"'!$O$42:$O$130"),C28),"Pricelist not found"),"") | G28: =IFERROR(E28*F28,"")
C29: # Entra ID Seats (unlimited Acronis Hosted Cloud Storage included*) | F29: =IF(E29>0,0,"") | G29: =IFERROR(E29*F29,"")
C30: # Entra ID Seats (for SP/Azure/Google Hosted Storage) | F30: =IF(E30>0,0,"") | G30: =IFERROR(E30*F30,"")
C31: # Google Workspace Seats (unlimited Acronis Hosted Cloud Storage included*) | F31: =IF(E31>0,IFERROR(SUMIFS(INDIRECT("'Pricelist "&'Solution-based'!$B$3&"'!$"&CHAR(70+$D$3)&"$42:$"&CHAR(70+$D$3)&"$130"),INDIRECT("'Pricelist "&'Solution-based'!$B$3&"'!$O$42:$O$130"),C31,INDIRECT("'Pricelist "&'Solution-based'!$B$3&"'!$E$42:$E$130"),$E$4),"Pricelist not found"),"") | G31: =IFERROR(E31*F31,"")
C32: # Google Workspace Seats (for SP/Azure/Google Hosted Storage) | F32: =IF(E32>0,IFERROR(SUMIFS(INDIRECT("'Pricelist "&'Solution-based'!$B$3&"'!$"&CHAR(70+$D$3)&"$42:$"&CHAR(70+$D$3)&"$130"),INDIRECT("'Pricelist "&'Solution-based'!$B$3&"'!$O$42:$O$130"),C32),"Pricelist not found"),"") | G32: =IFERROR(E32*F32,"")
C33: # Mobile Devices | F33: =IF(E33>0,IFERROR(SUMIFS(INDIRECT("'Pricelist "&'Solution-based'!$B$3&"'!$"&CHAR(70+$D$3)&"$42:$"&CHAR(70+$D$3)&"$130"),INDIRECT("'Pricelist "&'Solution-based'!$B$3&"'!$O$42:$O$130"),C33),"Pricelist not found"),"") | G33: =IFERROR(E33*F33,"")
C34: Acronis Cloud Storage at Acronis Datacenter (for Per Workload model) | F34: =IF(E34>0,IFERROR(SUMIFS(INDIRECT("'Pricelist "&'Solution-based'!$B$3&"'!$"&CHAR(70+$D$3)&"$42:$"&CHAR(70+$D$3)&"$130"),INDIRECT("'Pricelist "&'Solution-based'!$B$3&"'!$O$42:$O$130"),C34,INDIRECT("'Pricelist "&'Solution-based'!$B$3&"'!$E$42:$E$130"),$E$4),"Pricelist not found"),"") | G34: =IFERROR(E34*F34,"")
C35: Acronis Cloud Storage at Azure/Google datacenters (for Per Workload model) | F35: =IF(E35>0,IFERROR(SUMIFS(INDIRECT("'Pricelist "&'Solution-based'!$B$3&"'!$"&CHAR(70+$D$3)&"$42:$"&CHAR(70+$D$3)&"$130"),INDIRECT("'Pricelist "&'Solution-based'!$B$3&"'!$O$42:$O$130"),C35),"Pricelist not found"),"") | G35: =IFERROR(E35*F35,"")
B36: Per GB | C36: Acronis Cloud Storage at Acronis Datacenter (for Per GB model) | D36: Yes | F36: =IF(E36>0,IFERROR(SUMIFS(INDIRECT("'Pricelist "&'Solution-based'!$B$3&"'!$"&CHAR(70+$D$3)&"$42:$"&CHAR(70+$D$3)&"$130"),INDIRECT("'Pricelist "&'Solution-based'!$B$3&"'!$O$42:$O$130"),C36,INDIRECT("'Pricelist "&'Solution-based'!$B$3&"'!$E$42:$E$130"),$E$4),"Pricelist not found"),"") | G36: =IFERROR(E36*F36,"")
C37: Acronis Cloud Storage at Azure/Google datacenters (for Per GB model) | F37: =IF(E37>0,IFERROR(SUMIFS(INDIRECT("'Pricelist "&'Solution-based'!$B$3&"'!$"&CHAR(70+$D$3)&"$42:$"&CHAR(70+$D$3)&"$130"),INDIRECT("'Pricelist "&'Solution-based'!$B$3&"'!$O$42:$O$130"),C37),"Pricelist not found"),"") | G37: =IFERROR(E37*F37,"")
C38: Cloud - Service Provider Hosted Storage | F38: =IF(E38>0,IFERROR(SUMIFS(INDIRECT("'Pricelist "&'Solution-based'!$B$3&"'!$"&CHAR(70+$D$3)&"$42:$"&CHAR(70+$D$3)&"$130"),INDIRECT("'Pricelist "&'Solution-based'!$B$3&"'!$O$42:$O$130"),C38),"Pricelist not found"),"") | G38: =IFERROR(E38*F38,"")
C39: Customer Storage | F39: =IF(E39>0,IFERROR(SUMIFS(INDIRECT("'Pricelist "&'Solution-based'!$B$3&"'!$"&CHAR(70+$D$3)&"$42:$"&CHAR(70+$D$3)&"$130"),INDIRECT("'Pricelist "&'Solution-based'!$B$3&"'!$O$42:$O$130"),C39),"Pricelist not found"),"") | G39: =IFERROR(E39*F39,"")
B40: Microsoft 365 Backup from Microsoft | C40: Microsoft 365 Backup Storage powered by Microsoft (per GB, for both per GB and per workload models) | D40: Yes | F40: =IF(E40>0,IFERROR(SUMIFS(INDIRECT("'Pricelist "&'Solution-based'!$B$3&"'!$"&CHAR(70+$D$3)&"$42:$"&CHAR(70+$D$3)&"$130"),INDIRECT("'Pricelist "&'Solution-based'!$B$3&"'!$O$42:$O$130"),C40),"Pricelist not found"),"") | G40: =IFERROR(E40*F40,"")
...

Sheet Pricelist USD
A1: Group | D1: SKU Name | E1: DC group | F1: SKU | G1: Commitment 1 | H1: Commitment 2 | I1: Commitment 3 | J1: Commitment 4 | K1: Commitment 5 | L1: Commitment 6 | M1: Commitment 7 | N1: Commitment 8 | O1: This is master version. Other pricelists should do vlookup with this one (and add any SKUs afterwards, if SKU not present in US)
G2: 250 | H2: 500 | I2: 1000 | J2: 2000 | K2: 4000 | L2: 7000 | M2: 10000 | N2: 15000
A3: Solution- based Licensing | B3: Security + RMM | D3: Security + RMM - WL - Endpoint - Acronis Cyber Protect Cloud | E3: All | F3: SESDMSENS | G3: 2.8 | H3: 2.6 | I3: 2.29 | J3: 1.99 | K3: 1.65 | L3: 1.58 | M3: 1.5 | N3: 1.47 | O3: ='Solution-based'!C8 -> # Endpoint Security (Servers, VMs, Workstations)
D4: Security + RMM - WL - Microsoft 365 seat - Acronis Cyber Protect Cloud | E4: All | F4: SESEMSENS | G4: 3.2 | H4: 3.1 | I4: 3.01 | J4: 2.86 | K4: 2.72 | L4: 2.61 | M4: 2.51 | N4: 2.46 | O4: ='Solution-based'!C9 -> # Microsoft 365 Security
D5: Security + RMM - WL - Google Workspace seat - Acronis Cyber Protect Cloud | E5: All | F5: SESFMSENS | G5: 2.4 | H5: 2.33 | I5: 2.26 | J5: 2.15 | K5: 2.04 | L5: 1.96 | M5: 1.88 | N5: 1.84 | O5: ='Solution-based'!C10 -> # Google Workspace Security
B6: Backup and Disaster Recovery | C6: G1 DC group | D6: BDR - WL - Server (3 TB of Acronis Hosted Storage included) - G1 - Acronis Cyber Protect Cloud | E6: G1 | F6: SBDAMSENS | G6: 65 | H6: 60.45 | I6: 55.61 | J6: 50.05 | K6: 46.05 | L6: 44.21 | M6: 42 | N6: 41.16 | O6: ='Solution-based'!C11 -> # BDR Server (3 TB of Acronis Hosted Storage included)
D7: BDR - WL - VM (2 TB of Acronis Hosted Storage included) - G1 - Acronis Cyber Protect Cloud | E7: G1 | F7: SBDBMSENS | G7: 45 | H7: 41.85 | I7: 38.5 | J7: 34.65 | K7: 31.88 | L7: 30.6 | M7: 29.07 | N7: 28.49 | O7: ='Solution-based'!C12 -> # BDR Virtual Machine (2 TB of Acronis Hosted Storage included)
D8: BDR - WL - Workstation (300 GB of Acronis Hosted Storage included) - G1 - Acronis Cyber Protect Cloud | E8: G1 | F8: SBDCMSENS | G8: 9 | H8: 8.37 | I8: 7.7 | J8: 6.55 | K8: 5.9 | L8: 5.55 | M8: 5.11 | N8: 5.01 | O8: ='Solution-based'!C13 -> # BDR Workstation (300 GB of Acronis Hosted Storage included)
D9: BDR - WL - Microsoft 365 seat (unlimited Acronis Hosted Cloud Storage included1) - G1 - Acronis Cyber Protect Cloud | E9: G1 | F9: SBDDMSENS | G9: 3 | H9: 2.85 | I9: 2.65 | J9: 2.39 | K9: 2.2 | L9: 2.11 | M9: 2.03 | N9: 1.99 | O9: ='Solution-based'!C14 -> # Microsoft 365 Backup + Archiving (unlimited Acronis Hosted Cloud Storage included*)
D10: BDR - WL - Google Workspace seat (unlimited Acronis Hosted Cloud Storage included1) - G1 - Acronis Cyber Protect Cloud | E10: G1 | F10: SBDEMSENS | G10: 2.4 | H10: 2.28 | I10: 2.12 | J10: 1.91 | K10: 1.76 | L10: 1.69 | M10: 1.62 | N10: 1.59 | O10: ='Solution-based'!C15 -> # Google Workspace Backup (unlimited Acronis Hosted Cloud Storage included*)
D11: BDR - WL - Mobile Backup (50 GB of Acronis Hosted Storage included) - G1 - Acronis Cyber Protect Cloud | E11: G1 | F11: SBDGMSENS | G11: 2 | H11: 1.84 | I11: 1.69 | J11: 1.4 | K11: 1.19 | L11: 1.14 | M11: 1.09 | N11: 1.06 | O11: ='Solution-based'!C16 -> # Mobile Backup (50 GB od Acronis Hosted Storage included)
C12: G2 DC group | D12: BDR - WL - Server (3 TB of Acronis Hosted Storage included) - G2 - Acronis Cyber Protect Cloud | E12: G2 | F12: SBDHMSENS | G12: 81.5 | H12: 75.8 | I12: 69.74 | J12: 62.77 | K12: 57.75 | L12: 55.44 | M12: 52.67 | N12: 51.62 | O12: ='Solution-based'!C11 -> # BDR Server (3 TB of Acronis Hosted Storage included)
D13: BDR - WL - VM (2 TB of Acronis Hosted Storage included) - G2 - Acronis Cyber Protect Cloud | E13: G2 | F13: SBDIMSENS | G13: 56.5 | H13: 52.55 | I13: 48.35 | J13: 43.52 | K13: 40.04 | L13: 38.44 | M13: 36.52 | N13: 35.79 | O13: ='Solution-based'!C12 -> # BDR Virtual Machine (2 TB of Acronis Hosted Storage included)
D14: BDR - WL - Workstation (300 GB of Acronis Hosted Storage included) - G2 - Acronis Cyber Protect Cloud | E14: G2 | F14: SBDJMSENS | G14: 11.3 | H14: 10.51 | I14: 9.67 | J14: 8.51 | K14: 7.74 | L14: 7.28 | M14: 6.84 | N14: 6.7 | O14: ='Solution-based'!C13 -> # BDR Workstation (300 GB of Acronis Hosted Storage included)
D15: BDR - WL - Microsoft 365 seat (unlimited Acronis Hosted Cloud Storage included1) - G2 - Acronis Cyber Protect Cloud | E15: G2 | F15: SBDKMSENS | G15: 4.1 | H15: 3.9 | I15: 3.63 | J15: 3.27 | K15: 3.01 | L15: 2.89 | M15: 2.77 | N15: 2.71 | O15: ='Solution-based'!C14 -> # Microsoft 365 Backup + Archiving (unlimited Acronis Hosted Cloud Storage included*)
D16: BDR - WL - Google Workspace seat (unlimited Acronis Hosted Cloud Storage included1) - G2 - Acronis Cyber Protect Cloud | E16: G2 | F16: SBDLMSENS | G16: 3.22 | H16: 3.06 | I16: 2.85 | J16: 2.57 | K16: 2.36 | L16: 2.27 | M16: 2.18 | N16: 2.14 | O16: ='Solution-based'!C15 -> # Google Workspace Backup (unlimited Acronis Hosted Cloud Storage included*)
D17: BDR - WL - Mobile Backup (50 GB of Acronis Hosted Storage included) - G2 - Acronis Cyber Protect Cloud | E17: G2 | F17: SBDNMSENS | G17: 2.3 | H17: 2.12 | I17: 1.95 | J17: 1.62 | K17: 1.38 | L17: 1.32 | M17: 1.27 | N17: 1.23 | O17: ='Solution-based'!C16 -> # Mobile Backup (50 GB od Acronis Hosted Storage included)
B18: Ultimate Protection | C18: G1 DC group | D18: Ultimate Protection - WL - Server (3 TB of Acronis Hosted Storage included) - G1 - Acronis Cyber Protect Cloud | E18: G1 | F18: SUPCMSENS | G18: 71 | H18: 66.03 | I18: 60.75 | J18: 54.68 | K18: 51.95 | L18: 50.39 | M18: 48.88 | N18: 47.9 | O18: ='Solution-based'!C17 -> # Ultimate Server (3 TB of Acronis Hosted Storage included)
D19: Ultimate Protection - WL - VM (2 TB of Acronis Hosted Storage included) - G1 - Acronis Cyber Protect Cloud | E19: G1 | F19: SUPDMSENS | G19: 50 | H19: 46.5 | I19: 43.25 | J19: 40.66 | K19: 39.03 | L19: 37.86 | M19: 37.1 | N19: 36.36 | O19: ='Solution-based'!C18 -> # Ultimate Virtual Machine (2 TB of Acronis Hosted Storage included)
D20: Ultimate Protection - WL - Workstation (300 GB of Acronis Hosted Storage included) - G1 - Acronis Cyber Protect Cloud | E20: G1 | F20: SUPEMSENS | G20: 13.5 | H20: 12.56 | I20: 11.56 | J20: 10.17 | K20: 9.25 | L20: 8.7 | M20: 8.18 | N20: 8.02 | O20: ='Solution-based'!C19 -> # Ultimate Workstation (300 GB of Acronis Hosted Storage included)
D21: Ultimate Protection - WL - Microsoft 365 seat (unlimited Acronis Hosted Cloud Storage included1) - G1 - Acronis Cyber Protect Cloud | E21: G1 | F21: SUPFMSENS | G21: 8.2 | H21: 7.79 | I21: 7.32 | J21: 6.73 | K21: 6.19 | L21: 6 | M21: 5.82 | N21: 5.7 | O21: ='Solution-based'!C20 -> # Ultimate Microsoft 365 (unlimited Acronis Hosted Cloud Storage included*)
D22: Ultimate Protection - WL - Google Workspace seat (unlimited Acronis Hosted Cloud Storage included1) - G1 - Acronis Cyber Protect Cloud | E22: G1 | F22: SUPGMSENS | G22: 4.5 | H22: 4.28 | I22: 4.02 | J22: 3.7 | K22: 3.4 | L22: 3.3 | M22: 3.2 | N22: 3.14 | O22: ='Solution-based'!C21 -> # Ultimate Google Workspace (unlimited Acronis Hosted Cloud Storage included*)
C23: G2 DC group | D23: Ultimate Protection - WL - Server (3 TB of Acronis Hosted Storage included) - G2 - Acronis Cyber Protect Cloud | E23: G2 | F23: SUPHMSENS | G23: 87.5 | H23: 81.38 | I23: 74.87 | J23: 67.38 | K23: 64.01 | L23: 62.09 | M23: 60.23 | N23: 59.03 | O23: ='Solution-based'!C17 -> # Ultimate Server (3 TB of Acronis Hosted Storage included)
D24: Ultimate Protection - WL - VM (2 TB of Acronis Hosted Storage included) - G2 - Acronis Cyber Protect Cloud | E24: G2 | F24: SUPIMSENS | G24: 61.5 | H24: 57.2 | I24: 53.2 | J24: 50.01 | K24: 48.01 | L24: 46.57 | M24: 45.64 | N24: 44.73 | O24: ='Solution-based'!C18 -> # Ultimate Virtual Machine (2 TB of Acronis Hosted Storage included)
D25: Ultimate Protection - WL - Workstation (300 GB of Acronis Hosted Storage included) - G2 - Acronis Cyber Protect Cloud | E25: G2 | F25: SUPJMSENS | G25: 16.2 | H25: 15.07 | I25: 13.86 | J25: 12.2 | K25: 11.1 | L25: 10.43 | M25: 9.8 | N25: 9.6 | O25: ='Solution-based'!C19 -> # Ultimate Workstation (300 GB of Acronis Hosted Storage included)
D26: Ultimate Protection - WL - Microsoft 365 seat (unlimited Acronis Hosted Cloud Storage included1) - G2 - Acronis Cyber Protect Cloud | E26: G2 | F26: SUPKMSENS | G26: 9.5 | H26: 9.03 | I26: 8.49 | J26: 7.81 | K26: 7.19 | L26: 6.97 | M26: 6.76 | N26: 6.62 | O26: ='Solution-based'!C20 -> # Ultimate Microsoft 365 (unlimited Acronis Hosted Cloud Storage included*)
D27: Ultimate Protection - WL - Google Workspace seat (unlimited Acronis Hosted Cloud Storage included1) - G2 - Acronis Cyber Protect Cloud | E27: G2 | F27: SUPLMSENS | G27: 5.35 | H27: 5.08 | I27: 4.78 | J27: 4.4 | K27: 4.05 | L27: 3.93 | M27: 3.81 | N27: 3.73 | O27: ='Solution-based'!C21 -> # Ultimate Google Workspace (unlimited Acronis Hosted Cloud Storage included*)
B28: Managed Detection and Response | D28: Solution-based Licensing - WL - Managed Detection and Response by Acronis TRU - Partner-level - Standard - Acronis Cyber Protect Cloud | E28: All | F28: SRS8MSENS | G28: 1.9 | H28: 1.8 | I28: 1.7 | J28: 1.65 | K28: 1.6 | L28: 1.55 | M28: 1.5 | N28: 1.45 | O28: ='Solution-based'!C23 -> # Standard In-house MDR Workloads for Solution-Base Licensing, Partner-level (Servers, VMs, Workstations, Hosting Servers)
D29: Solution-based Licensing - WL - Managed Detection and Response by Acronis TRU - Partner-level - Advanced - Acronis Cyber Protect Cloud | E29: All | F29: SRS9MSENS | G29: 3.2 | H29: 3 | I29: 2.9 | J29: 2.8 | K29: 2.7 | L29: 2.6 | M29: 2.5 | N29: 2.4 | O29: ='Solution-based'!C24 -> # Advanced In-house MDR Workloads for Solution-Base Licensing, Partner-level (Servers, VMs, Workstations, Hosting Servers)
D30: Solution-based Licensing - WL - Managed Detection and Response by Acronis TRU - Customer-level - Standard - Acronis Cyber Protect Cloud | E30: All | F30: SRSVMSENS | G30: 2.4 | H30: 2.3 | I30: 2.2 | J30: 2.15 | K30: 2.1 | L30: 2.05 | M30: 2 | N30: 1.95 | O30: ='Solution-based'!C25 -> # Standard In-house MDR Workloads for Solution-Base Licensing, Customer-level (Servers, VMs, Workstations, Hosting Servers)
D31: Solution-based Licensing - WL - Managed Detection and Response by Acronis TRU - Customer-level - Advanced - Acronis Cyber Protect Cloud | E31: All | F31: SRSWMSENS | G31: 3.7 | H31: 3.5 | I31: 3.4 | J31: 3.3 | K31: 3.2 | L31: 3.1 | M31: 3 | N31: 2.9 | O31: ='Solution-based'!C26 -> # Advanced In-house MDR Workloads for Solution-Base Licensing, Customer-level (Servers, VMs, Workstations, Hosting Servers)
D32: Solution-based Licensing - WL - Managed Detection and Response - 3rd party - Standard - Acronis Cyber Protect Cloud | E32: All | F32: SRS6MSENS | G32: 3.2 | H32: 3.1 | I32: 3 | J32: 2.9 | K32: 2.8 | L32: 2.78 | M32: 2.75 | N32: 2.69 | O32: ='Solution-based'!C27 -> # Standard 3rd Party MDR Workloads for Solution-Base Licensing (Servers, VMs, Workstations, Hosting Servers)
D33: Solution-based Licensing - WL - Managed Detection and Response - 3rd party - Advanced - Acronis Cyber Protect Cloud | E33: All | F33: SRS7MSENS | G33: 6.4 | H33: 6.2 | I33: 6 | J33: 5.8 | K33: 5.6 | L33: 5.55 | M33: 5.5 | N33: 5.37 | O33: ='Solution-based'!C28 -> # Advanced 3rd Party MDR Workloads for Solution-Base Licensing (Servers, VMs, Workstations, Hosting Servers)
B34: Security Awareness Training | D34: Solution-based Licensing - Security Awareness Training (per user) - Acronis Cyber Protect Cloud | E34: All | F34: SBSTFNLOS | G34: 1.4 | H34: 1.33 | I34: 1.24 | J34: 1.12 | K34: 1.03 | L34: 0.99 | M34: 0.95 | N34: 0.93 | O34: ='Solution-based'!C29 -> # Security Awareness Training for Solution-based Licensing (Users)
B35: Additional Storage | D35: Solution-based Licensing - Acronis Hosted Storage (per GB) - G1 - Acronis Cyber Protect Cloud | E35: G1 | F35: SPSAMSENS | G35: 0.0435 | H35: 0.0387 | I35: 0.0341 | J35: 0.0286 | K35: 0.0232 | L35: 0.0218 | M35: 0.0209 | N35: 0.0203 | O35: ='Solution-based'!C30 -> Acronis Cloud Storage at Acronis Datacenter (for Solution-based Licensing overages)
D36: Solution-based Licensing - Acronis Hosted Storage (per GB) - G2 - Acronis Cyber Protect Cloud | E36: G2 | F36: SPS2MSENS | G36: 0.0546 | H36: 0.0486 | I36: 0.0428 | J36: 0.036 | K36: 0.0292 | L36: 0.0274 | M36: 0.0263 | N36: 0.0258 | O36: ='Solution-based'!C30 -> Acronis Cloud Storage at Acronis Datacenter (for Solution-based Licensing overages)
B37: Geo-Replication | D37: Solution-based Licensing - Geo-redundant - GB - Acronis Hosted Storage - G1 - Acronis Cyber Protect Cloud 4 | E37: G1 | F37: SPSGMSENS | G37: 0.0325 | H37: 0.0289 | I37: 0.0254 | J37: 0.0216 | K37: 0.0177 | L37: 0.0166 | M37: 0.0159 | N37: 0.0154 | O37: ='Solution-based'!C31 -> Solution-based licensing - Backup Geo-redundant - Acronis Hosted Storage
D38: Solution-based Licensing - Geo-redundant - WL - Microsoft 365 seat (unlimited Acronis Hosted Cloud storage1) - G1 - Acronis Cyber Protect Cloud 4 | E38: G1 | F38: SRSGMSENS | G38: 1.73 | H38: 1.64 | I38: 1.53 | J38: 1.38 | K38: 1.27 | L38: 1.22 | M38: 1.17 | N38: 1.15 | O38: ='Solution-based'!C32 -> Solution-based licensing - # Geo-redundant Microsoft 365 seat (unlimited Acronis Hosted Cloud Storage included*)
D39: Solution-based Licensing - Geo-redundant - WL - Google Workspace seat (unlimited Acronis Hosted Cloud storage1) - G1 - Acronis Cyber Protect Cloud 4 | E39: G1 | F39: SQSGMSENS | G39: 1.73 | H39: 1.64 | I39: 1.53 | J39: 1.38 | K39: 1.27 | L39: 1.22 | M39: 1.17 | N39: 1.15 | O39: ='Solution-based'!C33 -> Solution-based licensing - # Geo-redundant Google Workspace seat (unlimited Acronis Hosted Cloud Storage included*)
B40: Disaster Recovery Infrastructure | D40: Solution-based Licensing - Disaster Recovery - Acronis Hosted - 1 compute point (per running hour) - Acronis Cyber Protect Cloud | E40: All | F40: SQSAMSENS | G40: 0.06 | H40: 0.0558 | I40: 0.0513 | J40: 0.0462 | K40: 0.0425 | L40: 0.0408 | M40: 0.0388 | N40: 0.038 | O40: ='Solution-based'!C34 -> Monthly Compute Point Consumption for BDR/Ultimate
...

Sheet Compute points
A1: This section of the calculator helps to estimate the number of compute points required for tests with the default settings.
A3: Fill in the number of servers of each configuration template that will be used during Disaster Recovery. It is recommended to choose a configuration template of higher or equal specifications of the original server. I.e. if a server has 4 CPU and 8 GB of RAM - the closest template with a higher configuration is 4 vCore and 16 GB of RAM
A4: Server Template | B4: Compute Points per hour | C4: Number of servers (Solution-based licensing) | D4: Number of servers (Service-based licensing) | E4: Monthly Compute Points for Disaster Recovery Tests (Solution-based licensing) | F4: Monthly Compute Points for Disaster Recovery Tests (Service-based licensing)
A5: 1 vCore, 2 GB RAM | B5: 1 | E5: =C5*B5*$B$16*$B$17 -> 0 | F5: =D5*B5*$B$16*$B$17 -> 0
A6: 1 vCore, 4 GB RAM | B6: 2 | E6: =C6*B6*$B$16*$B$17 -> 0 | F6: =D6*B6*$B$16*$B$17 -> 0
A7: 2 vCore, 8 GB RAM | B7: 4 | E7: =C7*B7*$B$16*$B$17 -> 0 | F7: =D7*B7*$B$16*$B$17 -> 0
A8: 4 vCore, 16 GB RAM | B8: 8 | E8: =C8*B8*$B$16*$B$17 -> 0 | F8: =D8*B8*$B$16*$B$17 -> 0
A9: 8 vCore, 32 GB RAM | B9: 16 | E9: =C9*B9*$B$16*$B$17 -> 0 | F9: =D9*B9*$B$16*$B$17 -> 0
A10: 16 vCore, 64 GB RAM | B10: 32 | E10: =C10*B10*$B$16*$B$17 -> 0 | F10: =D10*B10*$B$16*$B$17 -> 0
A11: 16 vCore, 128 GB RAM | B11: 64 | E11: =C11*B11*$B$16*$B$17 -> 0 | F11: =D11*B11*$B$16*$B$17 -> 0
A12: 16 vCore, 256 GB RAM | B12: 128 | E12: =C12*B12*$B$16*$B$17 -> 0 | F12: =D12*B12*$B$16*$B$17 -> 0
A13: Totals: | C13: =SUM(C5:C12) -> 0 | D13: =SUM(D5:D12) -> 0 | E13: =SUM(E5:E12) -> 0 | F13: =SUM(F5:F12) -> 0
A15: Default options:
A16: Number of tests per month | B16: 1
A17: Running time per failover test (hours) | B17: 1
A22: Advanced settings: compute points required for actual Disaster Recovery situations
A24: Time to recovert from Disaster - how much downtime is expected during a disaster scenario. How much time it will take replace faulty/destroyed hardware, install it on site and restore data recommended minimum - 7 days.
A26: Time to recover from server failure (days) | B26: 7
A28: Server Template | B28: Compute Points per hour | C28: Number of servers | D28: Projected compute points for 1 day of actual Disaster Recovery | E28: Total projected compute points for actual Disaster Recovery
A29: 1 vCore, 2 GB RAM | B29: 1 | D29: =C29*24*B29 -> 0 | E29: =B29*24*$B$26*C29 -> 0
A30: 1 vCore, 4 GB RAM | B30: 2 | D30: =C30*24*B30 -> 0 | E30: =B30*24*$B$26*C30 -> 0
A31: 2 vCore, 8 GB RAM | B31: 4 | D31: =C31*24*B31 -> 0 | E31: =B31*24*$B$26*C31 -> 0
A32: 4 vCore, 16 GB RAM | B32: 8 | D32: =C32*24*B32 -> 0 | E32: =B32*24*$B$26*C32 -> 0
A33: 8 vCore, 32 GB RAM | B33: 16 | D33: =C33*24*B33 -> 0 | E33: =B33*24*$B$26*C33 -> 0
A34: 16 vCore, 64 GB RAM | B34: 32 | D34: =C34*24*B34 -> 0 | E34: =B34*24*$B$26*C34 -> 0
A35: 16 vCore, 128 GB RAM | B35: 64 | D35: =C35*24*B35 -> 0 | E35: =B35*24*$B$26*C35 -> 0
A36: 16 vCore, 256 GB RAM | B36: 128 | D36: =C36*24*B36 -> 0 | E36: =B36*24*$B$26*C36 -> 0
A37: Totals: | C37: =SUM(C29:C36) -> 0 | D37: =SUM(D29:D36) -> 0 | E37: =SUM(E29:E36) -> 0
A38: Total projected costs: | D38: =D37*IF(C37>=0,IF('Service-based'!$D$3=1,SUMIFS(INDIRECT("'Pricelist "&'Solution-based'!$B$3&"'!$G$42:$G$130"),INDIRECT("'Pricelist "&'Solution-based'!$B$3&"'!$O$42:$O$130"),'Service-based'!C50),IF('Service-based'!$D$3=2,SUMIFS(INDIRECT("'Pricelist "&'Solution-based'!$B$3&"'!$H$42:$H$130"),INDIRECT("'Pricelist "&'Solution-based'!$B$3&"'!$O$42:$O$130"),'Service-based'!C50),IF('Service-based'!$D$3=3,SUMIFS(INDIRECT("'Pricelist "&'Solution-based'!$B$3&"'!$I$42:$I$130"),INDIRECT("'Pricelist "&'Solution-based'!$B$3&"'!$O$42:$O$130"),'Service-based'!C50),IF('Service-based'!$D$3=4,SUMIFS(INDIRECT("'Pricelist "&'Solution-based'!$B$3&"'!$J$42:$J$130"),INDIRECT("'Pricelist "&'Solution-based'!$B$3&"'!$O$42:$O$130"),'Service-based'!C50),IF('Service-based'!$D$3=5,SUMIFS(INDIRECT("'Pricelist "&'Solution-based'!$B$3&"'!$K$42:$K$130"),INDIRECT("'Pricelist "&'Solution-based'!$B$3&"'!$O$42:$O$130"),'Service-based'!C50),IF('Service-based'!$D$3=6,SUMIFS(INDIRECT("'Pricelist "&'Solution-based'!$B$3&"'!$L$42:$L$130"),INDIRECT("'Pricelist "&'Solution-based'!$B$3&"'!$O$42:$O$130"),'Service-based'!C50),IF('Service-based'!$D$3=7,SUMIFS(INDIRECT("'Pricelist "&'Solution-based'!$B$3&"'!$M$42:$M$130"),INDIRECT("'Pricelist "&'Solution-based'!$B$3&"'!$O$42:$O$130"),'Service-based'!C50),IF('Service-based'!$D$3=8,SUMIFS(INDIRECT("'Pricelist "&'Solution-based'!$B$3&"'!$N$42:$N$130"),INDIRECT("'Pricelist "&'Solution-based'!$B$3&"'!$O$42:$O$130"),'Service-based'!C50),"")))))))),"") -> 0 | E38: =E37*IF(D37>=0,IF('Service-based'!$D$3=1,SUMIFS(INDIRECT("'Pricelist "&'Solution-based'!$B$3&"'!$G$42:$G$130"),INDIRECT("'Pricelist "&'Solution-based'!$B$3&"'!$O$42:$O$130"),'Service-based'!C50),IF('Service-based'!$D$3=2,SUMIFS(INDIRECT("'Pricelist "&'Solution-based'!$B$3&"'!$H$42:$H$130"),INDIRECT("'Pricelist "&'Solution-based'!$B$3&"'!$O$42:$O$130"),'Service-based'!C50),IF('Service-based'!$D$3=3,SUMIFS(INDIRECT("'Pricelist "&'Solution-based'!$B$3&"'!$I$42:$I$130"),INDIRECT("'Pricelist "&'Solution-based'!$B$3&"'!$O$42:$O$130"),'Service-based'!C50),IF('Service-based'!$D$3=4,SUMIFS(INDIRECT("'Pricelist "&'Solution-based'!$B$3&"'!$J$42:$J$130"),INDIRECT("'Pricelist "&'Solution-based'!$B$3&"'!$O$42:$O$130"),'Service-based'!C50),IF('Service-based'!$D$3=5,SUMIFS(INDIRECT("'Pricelist "&'Solution-based'!$B$3&"'!$K$42:$K$130"),INDIRECT("'Pricelist "&'Solution-based'!$B$3&"'!$O$42:$O$130"),'Service-based'!C50),IF('Service-based'!$D$3=6,SUMIFS(INDIRECT("'Pricelist "&'Solution-based'!$B$3&"'!$L$42:$L$130"),INDIRECT("'Pricelist "&'Solution-based'!$B$3&"'!$O$42:$O$130"),'Service-based'!C50),IF('Service-based'!$D$3=7,SUMIFS(INDIRECT("'Pricelist "&'Solution-based'!$B$3&"'!$M$42:$M$130"),INDIRECT("'Pricelist "&'Solution-based'!$B$3&"'!$O$42:$O$130"),'Service-based'!C50),IF('Service-based'!$D$3=8,SUMIFS(INDIRECT("'Pricelist "&'Solution-based'!$B$3&"'!$N$42:$N$130"),INDIRECT("'Pricelist "&'Solution-based'!$B$3&"'!$O$42:$O$130"),'Service-based'!C50),"")))))))),"") -> 0

Sheet Cloud DCs
A1: Acronis Datacenters
A2: # | B2: Type | C2: Storage type group | D2: Country | E2: DC | F2: Geo-redundancy available | G2: Cyber Employee available | H2: Cyber Frame Cloud available | I2: G1
A3: 1 | B3: Existing DC | C3: G1 | D3: USA | E3: Phoenix | F3: Yes | G3: Yes | H3: Yes | I3: G2
A4: 2 | B4: Existing DC | C4: G1 | D4: USA | E4: Ashburn | F4: Yes | G4: Yes | H4: Yes
A5: 3 | B5: Existing DC | C5: G1 | D5: Germany | E5: Frankfurt | F5: Yes | H5: Yes
A6: 4 | B6: Existing DC | C6: G1 | D6: Switzerland | E6: Lupfig | H6: Yes
A7: 5 | B7: Existing DC | C7: G1 | D7: UK | E7: London | F7: Yes | G7: Yes | H7: Yes
A8: 6 | B8: Existing DC | C8: G1 | D8: Japan | E8: Nagano | H8: Yes
A9: 7 | B9: Existing DC | C9: G1 | D9: Japan | E9: Kanagawa
A10: 8 | B10: Existing DC | C10: G1 | D10: Germany | E10: Cologne | F10: Yes | H10: Yes
A11: 9 | B11: Existing DC | C11: G1 | D11: France | E11: Strasbourg | H11: Yes
A12: 10 | B12: Existing DC | C12: G1 | D12: USA | E12: St.Louis | G12: Yes
A13: 11 | B13: Existing DC | C13: G1 | D13: Singapore | E13: Singapore | H13: Yes
A14: 12 | B14: Existing DC | C14: G1 | D14: Australia | E14: Sydney | G14: Yes | H14: Yes
A15: 13 | B15: Existing DC | C15: G1 | D15: Canada | E15: Vancouver | F15: Yes | G15: Yes | H15: Yes
A16: 14 | B16: Existing DC | C16: G1 | D16: Canada | E16: Toronto | F16: Yes | G16: Yes | H16: Yes
A17: 15 | B17: Existing DC | C17: G1 | D17: New Zealand | E17: Auckland | H17: Yes
A18: 16 | B18: Existing DC | C18: G1 | D18: Liechtenstein | E18: Balzers
A19: 17 | B19: Existing DC | C19: G1 | D19: Indonesia | E19: Jakarta | H19: Yes
A20: 18 | B20: Existing DC | C20: G1 | D20: India | E20: Mumbai | H20: Yes
A21: 19 | B21: Existing DC | C21: G1 | D21: Spain | E21: Valencia | H21: Yes
A22: 20 | B22: Existing DC | C22: G1 | D22: Israel | E22: Tel Aviv | H22: Yes
A23: 21 | B23: Existing DC | C23: G1 | D23: Portugal | E23: Lisbon | H23: Yes
A24: 22 | B24: Existing DC | C24: G1 | D24: Korea | E24: Seoul | H24: Yes
A25: 23 | B25: Existing DC | C25: G1 | D25: Czech Republic | E25: Prague | H25: Yes
A26: 24 | B26: Existing DC | C26: G1 | D26: Greece | E26: Thessaloniki | H26: Yes
A27: 25 | B27: Existing DC | C27: G1 | D27: Brazil | E27: Sao Paulo | F27: Yes | H27: Yes
A28: 26 | B28: Existing DC | C28: G1 | D28: Poland | E28: Warsaw | H28: Yes
A29: 27 | B29: Existing DC | C29: G1 | D29: Austria | E29: Vienna | H29: Yes
A30: 28 | B30: Existing DC | C30: G1 | D30: Denmark | E30: Billund | H30: Yes
A31: 29 | B31: Existing DC | C31: G1 | D31: Bulgaria | E31: Sofia | H31: Yes
A32: 30 | B32: Existing DC | C32: G1 | D32: Turkey | E32: Istanbul | H32: Yes
A33: 31 | B33: Existing DC | C33: G1 | D33: Norway | E33: Oslo | H33: Yes
A34: 32 | B34: Existing DC | C34: G1 | D34: Finland | E34: Helsinki | H34: Yes
A35: 33 | B35: Existing DC | C35: G1 | D35: Italy | E35: Rome | H35: Yes
A36: 34 | B36: Existing DC | C36: G1 | D36: Sweden | E36: Goteborg | H36: Yes
A37: 35 | B37: Existing DC | C37: G1 | D37: Mexico | E37: Mexico City | H37: Yes
A38: 36 | B38: Existing DC | C38: G1 | D38: Malaysia | E38: Kuala Lumpur | H38: Yes
A39: 37 | B39: Existing DC | C39: G2 | D39: South Africa | E39: Johannesburg | H39: Yes
... A41: 39 | B41: Existing DC | C41: G2 | D41: Taiwan | E41: Taipei | H41: Yes
...

Sheet Instructions
A2: How to use this calculator?
A3: 1. For customers using solution-based licensing, pricing should be calculated on this page.
A4: Solution-based licensing includes pre-packaged solutions that bundle services tailored to different workload types, helping partners build offerings for their end customers. Pre-packaged solutions include:
A5: a. Security + RMM - detection and response combined with remote monitoring and management capabilities
A6: b. Backup + DR - data protection capabilities with backup, disaster recovery and included storage
A7: c. Ultimate Protection - a comprehensive package that includes options (a) and (b), plus a range of additional services
A8: 2. For customers using service-based licensing, pricing should be calculated on this page.
A9: Service-based licensing offers standalone services that can be combined on demand and customized for each workload, maximizing flexibility. Available services include:
A10: a. Endpoint and SaaS backup
A11: b. Disaster Recovery
A12: c. Endpoint and SaaS security
A13: d. RMM
... A18: 5. The total cost is shown in the bottom of both solution-based and service-based pages. You can also see summarized totals with and without minimum commitment applied. Totals are synchronized and automatically updated when any changes are made.

Sheet Calculator -1 tier
A2: ='Solution-based'!D5-1 -> 0 | B2: 1. Choose Minimum commitment: | D2: {=INDEX(INDIRECT("'Pricelist "&'Solution-based'!$B$3&"'!$G$2:$N$2"),1,A2)} -> #VALUE!
B3: 2. Choose Datacenter Group: | D3: ='Solution-based'!E6 -> G1
B4: 3. Input data for endpoints to be licensed in per Workload model | D4: Quantity | E4: Price per unit (monthly) | F4: Cost
A5: Solution-based licensing | B5: Security+RMM | C5: ='Solution-based'!C8 -> # Endpoint Security (Servers, VMs, Workstations) | D5: =_xlfn.XLOOKUP(C5,'Solution-based'!$C$8:$C$49,'Solution-based'!$E$8:$E$49) -> 0 | E5: =IFERROR(IF(D5>0,SUMIFS(INDIRECT("'Pricelist "&'Solution-based'!$B$3&"'!$"&CHAR(70+$A$2)&"$3:$"&CHAR(70+$A$2)&"$130"),INDIRECT("'Pricelist "&'Solution-based'!$B$3&"'!$O$3:$O$130"),'Calculator +1 tier'!$C5),""),"Pricelist not found") | F5: =IFERROR(D5*E5,"")
C6: ='Solution-based'!C9 -> # Microsoft 365 Security | D6: =_xlfn.XLOOKUP(C6,'Solution-based'!$C$8:$C$49,'Solution-based'!$E$8:$E$49) -> 0 | E6: =IFERROR(IF(D6>0,SUMIFS(INDIRECT("'Pricelist "&'Solution-based'!$B$3&"'!$"&CHAR(70+$A$2)&"$3:$"&CHAR(70+$A$2)&"$130"),INDIRECT("'Pricelist "&'Solution-based'!$B$3&"'!$O$3:$O$130"),'Calculator +1 tier'!$C6),""),"Pricelist not found") | F6: =IFERROR(D6*E6,"")
C7: ='Solution-based'!C10 -> # Google Workspace Security | D7: =_xlfn.XLOOKUP(C7,'Solution-based'!$C$8:$C$49,'Solution-based'!$E$8:$E$49) -> 0 | E7: =IFERROR(IF(D7>0,SUMIFS(INDIRECT("'Pricelist "&'Solution-based'!$B$3&"'!$"&CHAR(70+$A$2)&"$3:$"&CHAR(70+$A$2)&"$130"),INDIRECT("'Pricelist "&'Solution-based'!$B$3&"'!$O$3:$O$130"),'Calculator +1 tier'!$C7),""),"Pricelist not found") | F7: =IFERROR(D7*E7,"")
B8: BDR | C8: ='Solution-based'!C11 -> # BDR Server (3 TB of Acronis Hosted Storage included) | D8: =_xlfn.XLOOKUP(C8,'Solution-based'!$C$8:$C$49,'Solution-based'!$E$8:$E$49) -> 0 | E8: =IFERROR(IF(D8>0,SUMIFS(INDIRECT("'Pricelist "&'Solution-based'!$B$3&"'!$"&CHAR(70+$A$2)&"$3:$"&CHAR(70+$A$2)&"$130"),INDIRECT("'Pricelist "&'Solution-based'!$B$3&"'!$O$3:$O$130"),'Calculator +1 tier'!$C8,INDIRECT("'Pricelist "&'Solution-based'!$B$3&"'!$E$3:$E$130"),$D$3),""),"Pricelist not found") | F8: =IFERROR(D8*E8,"")
C9: ='Solution-based'!C12 -> # BDR Virtual Machine (2 TB of Acronis Hosted Storage included) | D9: =_xlfn.XLOOKUP(C9,'Solution-based'!$C$8:$C$49,'Solution-based'!$E$8:$E$49) -> 0 | E9: =IFERROR(IF(D9>0,SUMIFS(INDIRECT("'Pricelist "&'Solution-based'!$B$3&"'!$"&CHAR(70+$A$2)&"$3:$"&CHAR(70+$A$2)&"$130"),INDIRECT("'Pricelist "&'Solution-based'!$B$3&"'!$O$3:$O$130"),'Calculator +1 tier'!$C9,INDIRECT("'Pricelist "&'Solution-based'!$B$3&"'!$E$3:$E$130"),$D$3),""),"Pricelist not found") | F9: =IFERROR(D9*E9,"")
C10: ='Solution-based'!C13 -> # BDR Workstation (300 GB of Acronis Hosted Storage included) | D10: =_xlfn.XLOOKUP(C10,'Solution-based'!$C$8:$C$49,'Solution-based'!$E$8:$E$49) -> 0 | E10: =IFERROR(IF(D10>0,SUMIFS(INDIRECT("'Pricelist "&'Solution-based'!$B$3&"'!$"&CHAR(70+$A$2)&"$3:$"&CHAR(70+$A$2)&"$130"),INDIRECT("'Pricelist "&'Solution-based'!$B$3&"'!$O$3:$O$130"),'Calculator +1 tier'!$C10,INDIRECT("'Pricelist "&'Solution-based'!$B$3&"'!$E$3:$E$130"),$D$3),""),"Pricelist not found") | F10: =IFERROR(D10*E10,"")
C11: ='Solution-based'!C14 -> # Microsoft 365 Backup + Archiving (unlimited Acronis Hosted Cloud Storage included*) | D11: =_xlfn.XLOOKUP(C11,'Solution-based'!$C$8:$C$49,'Solution-based'!$E$8:$E$49) -> 0 | E11: =IFERROR(IF(D11>0,SUMIFS(INDIRECT("'Pricelist "&'Solution-based'!$B$3&"'!$"&CHAR(70+$A$2)&"$3:$"&CHAR(70+$A$2)&"$130"),INDIRECT("'Pricelist "&'Solution-based'!$B$3&"'!$O$3:$O$130"),'Calculator +1 tier'!$C11,INDIRECT("'Pricelist "&'Solution-based'!$B$3&"'!$E$3:$E$130"),$D$3),""),"Pricelist not found") | F11: =IFERROR(D11*E11,"")
C12: ='Solution-based'!C15 -> # Google Workspace Backup (unlimited Acronis Hosted Cloud Storage included*) | D12: =_xlfn.XLOOKUP(C12,'Solution-based'!$C$8:$C$49,'Solution-based'!$E$8:$E$49) -> 0 | E12: =IFERROR(IF(D12>0,SUMIFS(INDIRECT("'Pricelist "&'Solution-based'!$B$3&"'!$"&CHAR(70+$A$2)&"$3:$"&CHAR(70+$A$2)&"$130"),INDIRECT("'Pricelist "&'Solution-based'!$B$3&"'!$O$3:$O$130"),'Calculator +1 tier'!$C12,INDIRECT("'Pricelist "&'Solution-based'!$B$3&"'!$E$3:$E$130"),$D$3),""),"Pricelist not found") | F12: =IFERROR(D12*E12,"")
C13: ='Solution-based'!C16 -> # Mobile Backup (50 GB od Acronis Hosted Storage included) | D13: =_xlfn.XLOOKUP(C13,'Solution-based'!$C$8:$C$49,'Solution-based'!$E$8:$E$49) -> 0 | E13: =IFERROR(IF(D13>0,SUMIFS(INDIRECT("'Pricelist "&'Solution-based'!$B$3&"'!$"&CHAR(70+$A$2)&"$3:$"&CHAR(70+$A$2)&"$130"),INDIRECT("'Pricelist "&'Solution-based'!$B$3&"'!$O$3:$O$130"),'Calculator +1 tier'!$C13,INDIRECT("'Pricelist "&'Solution-based'!$B$3&"'!$E$3:$E$130"),$D$3),""),"Pricelist not found") | F13: =IFERROR(D13*E13,"")
B14: Ultimate | C14: ='Solution-based'!C17 -> # Ultimate Server (3 TB of Acronis Hosted Storage included) | D14: =_xlfn.XLOOKUP(C14,'Solution-based'!$C$8:$C$49,'Solution-based'!$E$8:$E$49) -> 0 | E14: =IFERROR(IF(D14>0,SUMIFS(INDIRECT("'Pricelist "&'Solution-based'!$B$3&"'!$"&CHAR(70+$A$2)&"$3:$"&CHAR(70+$A$2)&"$130"),INDIRECT("'Pricelist "&'Solution-based'!$B$3&"'!$O$3:$O$130"),'Calculator +1 tier'!$C14,INDIRECT("'Pricelist "&'Solution-based'!$B$3&"'!$E$3:$E$130"),$D$3),""),"Pricelist not found") | F14: =IFERROR(D14*E14,"")
C15: ='Solution-based'!C18 -> # Ultimate Virtual Machine (2 TB of Acronis Hosted Storage included) | D15: =_xlfn.XLOOKUP(C15,'Solution-based'!$C$8:$C$49,'Solution-based'!$E$8:$E$49) -> 0 | E15: =IFERROR(IF(D15>0,SUMIFS(INDIRECT("'Pricelist "&'Solution-based'!$B$3&"'!$"&CHAR(70+$A$2)&"$3:$"&CHAR(70+$A$2)&"$130"),INDIRECT("'Pricelist "&'Solution-based'!$B$3&"'!$O$3:$O$130"),'Calculator +1 tier'!$C15,INDIRECT("'Pricelist "&'Solution-based'!$B$3&"'!$E$3:$E$130"),$D$3),""),"Pricelist not found") | F15: =IFERROR(D15*E15,"")
C16: ='Solution-based'!C19 -> # Ultimate Workstation (300 GB of Acronis Hosted Storage included) | D16: =_xlfn.XLOOKUP(C16,'Solution-based'!$C$8:$C$49,'Solution-based'!$E$8:$E$49) -> 0 | E16: =IFERROR(IF(D16>0,SUMIFS(INDIRECT("'Pricelist "&'Solution-based'!$B$3&"'!$"&CHAR(70+$A$2)&"$3:$"&CHAR(70+$A$2)&"$130"),INDIRECT("'Pricelist "&'Solution-based'!$B$3&"'!$O$3:$O$130"),'Calculator +1 tier'!$C16,INDIRECT("'Pricelist "&'Solution-based'!$B$3&"'!$E$3:$E$130"),$D$3),""),"Pricelist not found") | F16: =IFERROR(D16*E16,"")
C17: ='Solution-based'!C20 -> # Ultimate Microsoft 365 (unlimited Acronis Hosted Cloud Storage included*) | D17: =_xlfn.XLOOKUP(C17,'Solution-based'!$C$8:$C$49,'Solution-based'!$E$8:$E$49) -> 0 | E17: =IFERROR(IF(D17>0,SUMIFS(INDIRECT("'Pricelist "&'Solution-based'!$B$3&"'!$"&CHAR(70+$A$2)&"$3:$"&CHAR(70+$A$2)&"$130"),INDIRECT("'Pricelist "&'Solution-based'!$B$3&"'!$O$3:$O$130"),'Calculator +1 tier'!$C17,INDIRECT("'Pricelist "&'Solution-based'!$B$3&"'!$E$3:$E$130"),$D$3),""),"Pricelist not found") | F17: =IFERROR(D17*E17,"")
C18: ='Solution-based'!C21 -> # Ultimate Google Workspace (unlimited Acronis Hosted Cloud Storage included*) | D18: =_xlfn.XLOOKUP(C18,'Solution-based'!$C$8:$C$49,'Solution-based'!$E$8:$E$49) -> 0 | E18: =IFERROR(IF(D18>0,SUMIFS(INDIRECT("'Pricelist "&'Solution-based'!$B$3&"'!$"&CHAR(70+$A$2)&"$3:$"&CHAR(70+$A$2)&"$130"),INDIRECT("'Pricelist "&'Solution-based'!$B$3&"'!$O$3:$O$130"),'Calculator +1 tier'!$C18,INDIRECT("'Pricelist "&'Solution-based'!$B$3&"'!$E$3:$E$130"),$D$3),""),"Pricelist not found") | F18: =IFERROR(D18*E18,"")
B19: Managed Detection and Response | C19: ='Solution-based'!C23 -> # Standard In-house MDR Workloads for Solution-Base Licensing, Partner-level (Servers, VMs, Workstations, Hosting Servers) | D19: =_xlfn.XLOOKUP(C19,'Solution-based'!$C$8:$C$49,'Solution-based'!$E$8:$E$49) -> 0 | E19: =IFERROR(IF(D19>0,SUMIFS(INDIRECT("'Pricelist "&'Solution-based'!$B$3&"'!$"&CHAR(70+$A$2)&"$3:$"&CHAR(70+$A$2)&"$130"),INDIRECT("'Pricelist "&'Solution-based'!$B$3&"'!$O$3:$O$130"),'Calculator +1 tier'!$C19),""),"Pricelist not found") | F19: =IFERROR(D19*E19,"")
C20: ='Solution-based'!C24 -> # Advanced In-house MDR Workloads for Solution-Base Licensing, Partner-level (Servers, VMs, Workstations, Hosting Servers) | D20: =_xlfn.XLOOKUP(C20,'Solution-based'!$C$8:$C$49,'Solution-based'!$E$8:$E$49) -> 0 | E20: =IFERROR(IF(D20>0,SUMIFS(INDIRECT("'Pricelist "&'Solution-based'!$B$3&"'!$"&CHAR(70+$A$2)&"$3:$"&CHAR(70+$A$2)&"$130"),INDIRECT("'Pricelist "&'Solution-based'!$B$3&"'!$O$3:$O$130"),'Calculator +1 tier'!$C20),""),"Pricelist not found") | F20: =IFERROR(D20*E20,"")
C21: ='Solution-based'!C25 -> # Standard In-house MDR Workloads for Solution-Base Licensing, Customer-level (Servers, VMs, Workstations, Hosting Servers) | D21: =_xlfn.XLOOKUP(C21,'Solution-based'!$C$8:$C$49,'Solution-based'!$E$8:$E$49) -> 0 | E21: =IFERROR(IF(D21>0,SUMIFS(INDIRECT("'Pricelist "&'Solution-based'!$B$3&"'!$"&CHAR(70+$A$2)&"$3:$"&CHAR(70+$A$2)&"$130"),INDIRECT("'Pricelist "&'Solution-based'!$B$3&"'!$O$3:$O$130"),'Calculator +1 tier'!$C21),""),"Pricelist not found") | F21: =IFERROR(D21*E21,"")
C22: ='Solution-based'!C26 -> # Advanced In-house MDR Workloads for Solution-Base Licensing, Customer-level (Servers, VMs, Workstations, Hosting Servers) | D22: =_xlfn.XLOOKUP(C22,'Solution-based'!$C$8:$C$49,'Solution-based'!$E$8:$E$49) -> 0 | E22: =IFERROR(IF(D22>0,SUMIFS(INDIRECT("'Pricelist "&'Solution-based'!$B$3&"'!$"&CHAR(70+$A$2)&"$3:$"&CHAR(70+$A$2)&"$130"),INDIRECT("'Pricelist "&'Solution-based'!$B$3&"'!$O$3:$O$130"),'Calculator +1 tier'!$C22),""),"Pricelist not found") | F22: =IFERROR(D22*E22,"")
C23: ='Solution-based'!C27 -> # Standard 3rd Party MDR Workloads for Solution-Base Licensing (Servers, VMs, Workstations, Hosting Servers) | D23: =_xlfn.XLOOKUP(C23,'Solution-based'!$C$8:$C$49,'Solution-based'!$E$8:$E$49) -> 0 | E23: =IFERROR(IF(D23>0,SUMIFS(INDIRECT("'Pricelist "&'Solution-based'!$B$3&"'!$"&CHAR(70+$A$2)&"$3:$"&CHAR(70+$A$2)&"$130"),INDIRECT("'Pricelist "&'Solution-based'!$B$3&"'!$O$3:$O$130"),'Calculator +1 tier'!$C23),""),"Pricelist not found") | F23: =IFERROR(D23*E23,"")
C24: ='Solution-based'!C28 -> # Advanced 3rd Party MDR Workloads for Solution-Base Licensing (Servers, VMs, Workstations, Hosting Servers) | D24: =_xlfn.XLOOKUP(C24,'Solution-based'!$C$8:$C$49,'Solution-based'!$E$8:$E$49) -> 0 | E24: =IFERROR(IF(D24>0,SUMIFS(INDIRECT("'Pricelist "&'Solution-based'!$B$3&"'!$"&CHAR(70+$A$2)&"$3:$"&CHAR(70+$A$2)&"$130"),INDIRECT("'Pricelist "&'Solution-based'!$B$3&"'!$O$3:$O$130"),'Calculator +1 tier'!$C24),""),"Pricelist not found") | F24: =IFERROR(D24*E24,"")
